Workbook

Sheet Pivot
A3: Row Labels | B3: Sum of FY21 BOM | C3: Sum of FY22 BOM | F3: Material | G3: Description | H3: FY21 Usage | I3: FY22 Fcst
A4: 11309 | B4: 366.4 | C4: 1683 | F4: 11309 | G4: =VLOOKUP(F4,Master!$C$2:$E$1657,3,FALSE) -> Tergitol L-62 | H4: 366.4 | I4: 1683
A5: 11525 | B5: 831.31441 | C5: 636.3411 | F5: 11525 | G5: =VLOOKUP(F5,Master!$C$2:$E$1657,3,FALSE) -> ACID, BENZOIC, FMU, NON-CFR | H5: 831.31441 | I5: 636.3411
A6: 11694 | B6: 1179.2894 | C6: 22378.156 | F6: 11694 | G6: =VLOOKUP(F6,Master!$C$2:$E$1657,3,FALSE) -> ACID, CITRIC, USP, ANHYDROUS, POWDER | H6: 1179.2894 | I6: 22378.156
A7: 11907 | B7: 107385.96 | C7: 4112290.4 | F7: 11907 | G7: =VLOOKUP(F7,Master!$C$2:$E$1657,3,FALSE) -> PROPYLENE GLYCOL, BULK | H7: 107385.96 | I7: 4112290.4
A8: 12430 | B8: 293.11783 | C8: 454.48852 | F8: 12430 | G8: =VLOOKUP(F8,Master!$C$2:$E$1657,3,FALSE) -> ACID, PHOSPHORIC, NF | H8: 293.11783 | I8: 454.48852
A9: 12470 | B9: 145.35644 | C9: 12.113112 | F9: 12470 | G9: =VLOOKUP(F9,Master!$C$2:$E$1657,3,FALSE) -> ACID, PROPIONIC (NOT NF) | H9: 145.35644 | I9: 12.113112
A10: 12602 | B10: 73.302254 | C10: 0.46303016 | F10: 12602 | G10: =VLOOKUP(F10,Master!$C$2:$E$1657,3,FALSE) -> ACID, SULFURIC, 66 FOOD CHEMIC ALS CODEX | H10: 73.302254 | I10: 0.46303016
A11: 14340 | B11: 0 | C11: 0 | F11: 14340 | G11: =VLOOKUP(F11,Master!$C$2:$E$1657,3,FALSE) -> AMMONIUM PHOSPH, DIBASIC W/ TRICALC PH | H11: 0 | I11: 0
A12: 15633 | B12: 11210.4 | C12: 11846.625 | F12: 15633 | G12: =VLOOKUP(F12,Master!$C$2:$E$1657,3,FALSE) -> LIGNOSULFONATE CALCIUM (NORLIG 11 DA) | H12: 11210.4 | I12: 11846.625
A13: 18105 | B13: 86783.418 | C13: 86533.337 | F13: 18105 | G13: =VLOOKUP(F13,Master!$C$2:$E$1657,3,FALSE) -> SODIUM SULFATE | H13: 86783.418 | I13: 86533.337
A14: 20744 | B14: 0 | C14: 0 | F14: 20744 | G14: =VLOOKUP(F14,Master!$C$2:$E$1657,3,FALSE) -> CLAY, AIR-FLOATED, S CAROLINA KAOLIN | H14: 0 | I14: 0
A15: 20746 | B15: 352.78909 | C15: 308.39444 | F15: 20746 | G15: =VLOOKUP(F15,Master!$C$2:$E$1657,3,FALSE) -> CLAY, MMT, (BENTONE-38) | H15: 352.78909 | I15: 308.39444
... A62: A570292 | B62: 650.208 | C62: 873.196 | F62: A570292 | G62: =VLOOKUP(F62,Master!$C$2:$E$1657,3,FALSE) -> T-DET A 25-7 SURFACTANT | H62: 650.208 | I62: 873.196
A63: (blank) | C63: #N/A
A64: Grand Total | B64: 782340.64 | C64: #N/A

Sheet Master
A1: Material | B1: Material description | C1: Component | D1: Component Unit | E1: Description | F1: Header Unit | G1: Quantity | H1: Base quantity | I1: MRP Controller | J1: ASM Level | K1: FY21 Usage | L1: FY22 Fcst | M1: FY21 BOM | N1: FY22 BOM
A2: 025710701 | B2: PROMALIN 10 X 500 ML | C2: 11694 | D2: KG | E2: ACID, CITRIC, USP, ANHYDROUS, POWDER | F2: EA | G2: 2.605 | H2: 1000 | I2: 300 | J2: 2 | K2: =VLOOKUP(A2,[1]Sheet1!$A$2:$C$284,3,FALSE) -> 40 | L2: =VLOOKUP(A2,[2]Sheet1!$A$115:$F$749,6,FALSE) -> 0 | M2: =(G2*K2)/H2 -> 0.1042 | N2: =(L2*G2)/H2 -> 0
A3: 025710701 | B3: PROMALIN 10 X 500 ML | C3: 11907 | D3: KG | E3: PROPYLENE GLYCOL, BULK | F3: EA | G3: 499.223 | H3: 1000 | I3: 303 | J3: 2 | K3: =VLOOKUP(A3,[1]Sheet1!$A$2:$C$284,3,FALSE) -> 40 | L3: =VLOOKUP(A3,[2]Sheet1!$A$115:$F$749,6,FALSE) -> 0 | M3: =(G3*K3)/H3 -> 19.96892 | N3: =(L3*G3)/H3 -> 0
A4: 025710702 | B4: PROMALIN 1 X 200 LTR | C4: 11694 | D4: KG | E4: ACID, CITRIC, USP, ANHYDROUS, POWDER | F4: EA | G4: 1042 | H4: 1000 | I4: 300 | J4: 2 | K4: =VLOOKUP(A4,[1]Sheet1!$A$2:$C$284,3,FALSE) -> 18 | L4: =VLOOKUP(A4,[2]Sheet1!$A$115:$F$749,6,FALSE) -> 20010 | M4: =(G4*K4)/H4 -> 18.756 | N4: =(L4*G4)/H4 -> 20850.42
A5: 025710702 | B5: PROMALIN 1 X 200 LTR | C5: 11907 | D5: KG | E5: PROPYLENE GLYCOL, BULK | F5: EA | G5: 199688.88 | H5: 1000 | I5: 303 | J5: 2 | K5: =VLOOKUP(A5,[1]Sheet1!$A$2:$C$284,3,FALSE) -> 18 | L5: =VLOOKUP(A5,[2]Sheet1!$A$115:$F$749,6,FALSE) -> 20010 | M5: =(G5*K5)/H5 -> 3594.3998 | N5: =(L5*G5)/H5 -> 3995774.5
A6: 025711501 | B6: PROMALIN 10 X 500 ML | C6: 11694 | D6: KG | E6: ACID, CITRIC, USP, ANHYDROUS, POWDER | F6: EA | G6: 2.605 | H6: 1000 | I6: 300 | J6: 2 | K6: =VLOOKUP(A6,[1]Sheet1!$A$2:$C$284,3,FALSE) -> 2500 | L6: =VLOOKUP(A6,[2]Sheet1!$A$115:$F$749,6,FALSE) -> 500 | M6: =(G6*K6)/H6 -> 6.5125 | N6: =(L6*G6)/H6 -> 1.3025
A7: 025711501 | B7: PROMALIN 10 X 500 ML | C7: 11907 | D7: KG | E7: PROPYLENE GLYCOL, BULK | F7: EA | G7: 499.223 | H7: 1000 | I7: 303 | J7: 2 | K7: =VLOOKUP(A7,[1]Sheet1!$A$2:$C$284,3,FALSE) -> 2500 | L7: =VLOOKUP(A7,[2]Sheet1!$A$115:$F$749,6,FALSE) -> 500 | M7: =(G7*K7)/H7 -> 1248.0575 | N7: =(L7*G7)/H7 -> 249.6115
A8: 025711901 | B8: Promalin 10 X 500 ML | C8: 11694 | D8: KG | E8: ACID, CITRIC, USP, ANHYDROUS, POWDER | F8: EA | G8: 2.605 | H8: 1000 | I8: 300 | J8: 2 | K8: =VLOOKUP(A8,[1]Sheet1!$A$2:$C$284,3,FALSE) -> 2500 | L8: =VLOOKUP(A8,[2]Sheet1!$A$115:$F$749,6,FALSE) -> 800 | M8: =(G8*K8)/H8 -> 6.5125 | N8: =(L8*G8)/H8 -> 2.084
A9: 025711901 | B9: Promalin 10 X 500 ML | C9: 11907 | D9: KG | E9: PROPYLENE GLYCOL, BULK | F9: EA | G9: 499.223 | H9: 1000 | I9: 303 | J9: 2 | K9: =VLOOKUP(A9,[1]Sheet1!$A$2:$C$284,3,FALSE) -> 2500 | L9: =VLOOKUP(A9,[2]Sheet1!$A$115:$F$749,6,FALSE) -> 800 | M9: =(G9*K9)/H9 -> 1248.0575 | N9: =(L9*G9)/H9 -> 399.3784
A10: 025712001 | B10: PROMALIN 2 X 5 LT | C10: 11694 | D10: KG | E10: ACID, CITRIC, USP, ANHYDROUS, POWDER | F10: EA | G10: 26.05 | H10: 1000 | I10: 300 | J10: 2 | K10: =VLOOKUP(A10,[1]Sheet1!$A$2:$C$284,3,FALSE) -> 2000 | L10: =VLOOKUP(A10,[2]Sheet1!$A$115:$F$749,6,FALSE) -> 2100 | M10: =(G10*K10)/H10 -> 52.1 | N10: =(L10*G10)/H10 -> 54.705
A11: 025712001 | B11: PROMALIN 2 X 5 LT | C11: 11907 | D11: KG | E11: PROPYLENE GLYCOL, BULK | F11: EA | G11: 4992.222 | H11: 1000 | I11: 303 | J11: 2 | K11: =VLOOKUP(A11,[1]Sheet1!$A$2:$C$284,3,FALSE) -> 2000 | L11: =VLOOKUP(A11,[2]Sheet1!$A$115:$F$749,6,FALSE) -> 2100 | M11: =(G11*K11)/H11 -> 9984.444 | N11: =(L11*G11)/H11 -> 10483.666
A12: 025712003 | B12: PROMALIN 10 X 1 LT | C12: 11694 | D12: KG | E12: ACID, CITRIC, USP, ANHYDROUS, POWDER | F12: EA | G12: 5.21 | H12: 1000 | I12: 300 | J12: 2 | K12: =VLOOKUP(A12,[1]Sheet1!$A$2:$C$284,3,FALSE) -> 1300 | L12: =VLOOKUP(A12,[2]Sheet1!$A$115:$F$749,6,FALSE) -> 1300 | M12: =(G12*K12)/H12 -> 6.773 | N12: =(L12*G12)/H12 -> 6.773
A13: 025712003 | B13: PROMALIN 10 X 1 LT | C13: 11907 | D13: KG | E13: PROPYLENE GLYCOL, BULK | F13: EA | G13: 998.445 | H13: 1000 | I13: 303 | J13: 2 | K13: =VLOOKUP(A13,[1]Sheet1!$A$2:$C$284,3,FALSE) -> 1300 | L13: =VLOOKUP(A13,[2]Sheet1!$A$115:$F$749,6,FALSE) -> 1300 | M13: =(G13*K13)/H13 -> 1297.9785 | N13: =(L13*G13)/H13 -> 1297.9785
... A50: 051089401 | B50: VECTOBAC G 1 X 18.1 KG | C50: 63356 | D50: KG | E50: SILICON DIOXIDE (ZEOFREE 80) ( NOT NF) | F50: EA | G50: 0.035 | H50: 1000 | I50: 300 | J50: 3 | K50: =VLOOKUP(A50,[1]Sheet1!$A$2:$C$284,3,FALSE) -> 5143 | L50: =VLOOKUP(A50,[2]Sheet1!$A$115:$F$749,6,FALSE) -> 200 | M50: =(G50*K50)/H50 -> 0.180005 | N50: =(L50*G50)/H50 -> 0.007
A51: 051886901 | B51: Bactospeine PM 1 X 10 KG | C51: 63359 | D51: KG | E51: SILICON DIOXIDE,NOT NF,HYDRATE HI-SIL233 | F51: EA | G51: 250 | H51: 1000 | I51: 300 | J51: 2 | K51: 0 | L51: =VLOOKUP(A51,[2]Sheet1!$A$115:$F$749,6,FALSE) -> 0 | M51: =(G51*K51)/H51 -> 0 | N51: =(L51*G51)/H51 -> 0
A52: 051886901 | B52: Bactospeine PM 1 X 10 KG | C52: 70289 | D52: KG | E52: SURFACTANT, SURFYNOL - 485, NO N-CFR | F52: EA | G52: 199.98 | H52: 1000 | I52: 300 | J52: 2 | K52: 0 | L52: =VLOOKUP(A52,[2]Sheet1!$A$115:$F$749,6,FALSE) -> 0 | M52: =(G52*K52)/H52 -> 0 | N52: =(L52*G52)/H52 -> 0
A53: 051886901 | B53: Bactospeine PM 1 X 10 KG | C53: 20749 | D53: KG | E53: CLAY, WATER-WASHED, SPRAY-DRIED KAOLIN | F53: EA | G53: 6508.89 | H53: 1000 | I53: 300 | J53: 2 | K53: 0 | L53: =VLOOKUP(A53,[2]Sheet1!$A$115:$F$749,6,FALSE) -> 0 | M53: =(G53*K53)/H53 -> 0 | N53: =(L53*G53)/H53 -> 0
A54: 051886901 | B54: Bactospeine PM 1 X 10 KG | C54: 77425 | D54: KG | E54: SIPERNAT®807A (SODIUM ALUMINOSILICATE) | F54: EA | G54: 24.831 | H54: 1000 | I54: 300 | J54: 4 | K54: 0 | L54: =VLOOKUP(A54,[2]Sheet1!$A$115:$F$749,6,FALSE) -> 0 | M54: =(G54*K54)/H54 -> 0 | N54: =(L54*G54)/H54 -> 0
A55: 052080703 | B55: PROGIBB PLUS 1 X 25 KG | C55: 66741 | D55: KG | E55: SIPERNAT®807 SODIUM 00-9 ALUMINOSILICATE | F55: EA | G55: 1875 | H55: 1000 | I55: 300 | J55: 2 | K55: =VLOOKUP(A55,[1]Sheet1!$A$2:$C$284,3,FALSE) -> 0 | L55: =VLOOKUP(A55,[2]Sheet1!$A$115:$F$749,6,FALSE) -> 0 | M55: =(G55*K55)/H55 -> 0 | N55: =(L55*G55)/H55 -> 0
A56: 052080703 | B56: PROGIBB PLUS 1 X 25 KG | C56: 20744 | D56: KG | E56: CLAY, AIR-FLOATED, S CAROLINA KAOLIN | F56: EA | G56: 1875 | H56: 1000 | I56: 300 | J56: 2 | K56: =VLOOKUP(A56,[1]Sheet1!$A$2:$C$284,3,FALSE) -> 0 | L56: =VLOOKUP(A56,[2]Sheet1!$A$115:$F$749,6,FALSE) -> 0 | M56: =(G56*K56)/H56 -> 0 | N56: =(L56*G56)/H56 -> 0
A57: 052080703 | B57: PROGIBB PLUS 1 X 25 KG | C57: 14340 | D57: KG | E57: AMMONIUM PHOSPH, DIBASIC W/ TRICALC PH | F57: EA | G57: 18450 | H57: 1000 | I57: 300 | J57: 2 | K57: =VLOOKUP(A57,[1]Sheet1!$A$2:$C$284,3,FALSE) -> 0 | L57: =VLOOKUP(A57,[2]Sheet1!$A$115:$F$749,6,FALSE) -> 0 | M57: =(G57*K57)/H57 -> 0 | N57: =(L57*G57)/H57 -> 0
A58: 052081901 | B58: PROGIBB PLUS 20 X 100 GM | C58: 66741 | D58: KG | E58: SIPERNAT®807 SODIUM 00-9 ALUMINOSILICATE | F58: EA | G58: 7.5 | H58: 1000 | I58: 300 | J58: 2 | K58: =VLOOKUP(A58,[1]Sheet1!$A$2:$C$284,3,FALSE) -> 0 | L58: =VLOOKUP(A58,[2]Sheet1!$A$115:$F$749,6,FALSE) -> 0 | M58: =(G58*K58)/H58 -> 0 | N58: =(L58*G58)/H58 -> 0
A59: 052081901 | B59: PROGIBB PLUS 20 X 100 GM | C59: 20744 | D59: KG | E59: CLAY, AIR-FLOATED, S CAROLINA KAOLIN | F59: EA | G59: 7.5 | H59: 1000 | I59: 300 | J59: 2 | K59: =VLOOKUP(A59,[1]Sheet1!$A$2:$C$284,3,FALSE) -> 0 | L59: =VLOOKUP(A59,[2]Sheet1!$A$115:$F$749,6,FALSE) -> 0 | M59: =(G59*K59)/H59 -> 0 | N59: =(L59*G59)/H59 -> 0
A60: 052081901 | B60: PROGIBB PLUS 20 X 100 GM | C60: 14340 | D60: KG | E60: AMMONIUM PHOSPH, DIBASIC W/ TRICALC PH | F60: EA | G60: 73.8 | H60: 1000 | I60: 300 | J60: 2 | K60: =VLOOKUP(A60,[1]Sheet1!$A$2:$C$284,3,FALSE) -> 0 | L60: =VLOOKUP(A60,[2]Sheet1!$A$115:$F$749,6,FALSE) -> 0 | M60: =(G60*K60)/H60 -> 0 | N60: =(L60*G60)/H60 -> 0
A61: 052090702 | B61: DIPEL 2X 1 X 10 KG | C61: 77425 | D61: KG | E61: SIPERNAT®807A (SODIUM ALUMINOSILICATE) | F61: EA | G61: 46.915 | H61: 1000 | I61: 300 | J61: 4 | K61: =VLOOKUP(A61,[1]Sheet1!$A$2:$C$284,3,FALSE) -> 120 | L61: =VLOOKUP(A61,[2]Sheet1!$A$115:$F$749,6,FALSE) -> 0 | M61: =(G61*K61)/H61 -> 5.6298 | N61: =(L61*G61)/H61 -> 0
A62: 052090702 | B62: DIPEL 2X 1 X 10 KG | C62: 63359 | D62: KG | E62: SILICON DIOXIDE,NOT NF,HYDRATE HI-SIL233 | F62: EA | G62: 250 | H62: 1000 | I62: 300 | J62: 2 | K62: =VLOOKUP(A62,[1]Sheet1!$A$2:$C$284,3,FALSE) -> 120 | L62: =VLOOKUP(A62,[2]Sheet1!$A$115:$F$749,6,FALSE) -> 0 | M62: =(G62*K62)/H62 -> 30 | N62: =(L62*G62)/H62 -> 0
A63: 052090702 | B63: DIPEL 2X 1 X 10 KG | C63: 65785 | D63: KG | E63: SODIUM LIGNOSULFONATE (MARASPE RSE B-22) | F63: EA | G63: 1000 | H63: 1000 | I63: 300 | J63: 2 | K63: =VLOOKUP(A63,[1]Sheet1!$A$2:$C$284,3,FALSE) -> 120 | L63: =VLOOKUP(A63,[2]Sheet1!$A$115:$F$749,6,FALSE) -> 0 | M63: =(G63*K63)/H63 -> 120 | N63: =(L63*G63)/H63 -> 0
A64: 052090702 | B64: DIPEL 2X 1 X 10 KG | C64: 69662 | D64: KG | E64: LACTOSE (SUGAR OF MILK), CRUDE | F64: EA | G64: 2500 | H64: 1000 | I64: 300 | J64: 2 | K64: =VLOOKUP(A64,[1]Sheet1!$A$2:$C$284,3,FALSE) -> 120 | L64: =VLOOKUP(A64,[2]Sheet1!$A$115:$F$749,6,FALSE) -> 0 | M64: =(G64*K64)/H64 -> 300 | N64: =(L64*G64)/H64 -> 0
A65: 052090702 | B65: DIPEL 2X 1 X 10 KG | C65: 11309 | D65: KG | E65: Tergitol L-62 | F65: EA | G65: 200 | H65: 1000 | I65: 300 | J65: 2 | K65: =VLOOKUP(A65,[1]Sheet1!$A$2:$C$284,3,FALSE) -> 120 | L65: =VLOOKUP(A65,[2]Sheet1!$A$115:$F$749,6,FALSE) -> 0 | M65: =(G65*K65)/H65 -> 24 | N65: =(L65*G65)/H65 -> 0
A66: 052090704 | B66: DIPEL 2X 12 X 0.5 KG | C66: 77425 | D66: KG | E66: SIPERNAT®807A (SODIUM ALUMINOSILICATE) | F66: EA | G66: 2.346 | H66: 1000 | I66: 300 | J66: 4 | K66: 0 | L66: =VLOOKUP(A66,[2]Sheet1!$A$115:$F$749,6,FALSE) -> 0 | M66: =(G66*K66)/H66 -> 0 | N66: =(L66*G66)/H66 -> 0
A67: 052090704 | B67: DIPEL 2X 12 X 0.5 KG | C67: 63359 | D67: KG | E67: SILICON DIOXIDE,NOT NF,HYDRATE HI-SIL233 | F67: EA | G67: 12.5 | H67: 1000 | I67: 300 | J67: 2 | K67: 0 | L67: =VLOOKUP(A67,[2]Sheet1!$A$115:$F$749,6,FALSE) -> 0 | M67: =(G67*K67)/H67 -> 0 | N67: =(L67*G67)/H67 -> 0
A68: 052090704 | B68: DIPEL 2X 12 X 0.5 KG | C68: 65785 | D68: KG | E68: SODIUM LIGNOSULFONATE (MARASPE RSE B-22) | F68: EA | G68: 50 | H68: 1000 | I68: 300 | J68: 2 | K68: 0 | L68: =VLOOKUP(A68,[2]Sheet1!$A$115:$F$749,6,FALSE) -> 0 | M68: =(G68*K68)/H68 -> 0 | N68: =(L68*G68)/H68 -> 0
A69: 052090704 | B69: DIPEL 2X 12 X 0.5 KG | C69: 69662 | D69: KG | E69: LACTOSE (SUGAR OF MILK), CRUDE | F69: EA | G69: 125 | H69: 1000 | I69: 300 | J69: 2 | K69: 0 | L69: =VLOOKUP(A69,[2]Sheet1!$A$115:$F$749,6,FALSE) -> 0 | M69: =(G69*K69)/H69 -> 0 | N69: =(L69*G69)/H69 -> 0
A70: 052090704 | B70: DIPEL 2X 12 X 0.5 KG | C70: 11309 | D70: KG | E70: Tergitol L-62 | F70: EA | G70: 10 | H70: 1000 | I70: 300 | J70: 2 | K70: 0 | L70: =VLOOKUP(A70,[2]Sheet1!$A$115:$F$749,6,FALSE) -> 0 | M70: =(G70*K70)/H70 -> 0 | N70: =(L70*G70)/H70 -> 0
A71: 052091702 | B71: DIPEL 2X 12 X 0.5 KG | C71: 77425 | D71: KG | E71: SIPERNAT®807A (SODIUM ALUMINOSILICATE) | F71: EA | G71: 2.346 | H71: 1000 | I71: 300 | J71: 4 | K71: =VLOOKUP(A71,[1]Sheet1!$A$2:$C$284,3,FALSE) -> 0 | L71: =VLOOKUP(A71,[2]Sheet1!$A$115:$F$749,6,FALSE) -> 0 | M71: =(G71*K71)/H71 -> 0 | N71: =(L71*G71)/H71 -> 0
A72: 052091702 | B72: DIPEL 2X 12 X 0.5 KG | C72: 63359 | D72: KG | E72: SILICON DIOXIDE,NOT NF,HYDRATE HI-SIL233 | F72: EA | G72: 12.5 | H72: 1000 | I72: 300 | J72: 2 | K72: =VLOOKUP(A72,[1]Sheet1!$A$2:$C$284,3,FALSE) -> 0 | L72: =VLOOKUP(A72,[2]Sheet1!$A$115:$F$749,6,FALSE) -> 0 | M72: =(G72*K72)/H72 -> 0 | N72: =(L72*G72)/H72 -> 0
A73: 052091702 | B73: DIPEL 2X 12 X 0.5 KG | C73: 65785 | D73: KG | E73: SODIUM LIGNOSULFONATE (MARASPE RSE B-22) | F73: EA | G73: 50 | H73: 1000 | I73: 300 | J73: 2 | K73: =VLOOKUP(A73,[1]Sheet1!$A$2:$C$284,3,FALSE) -> 0 | L73: =VLOOKUP(A73,[2]Sheet1!$A$115:$F$749,6,FALSE) -> 0 | M73: =(G73*K73)/H73 -> 0 | N73: =(L73*G73)/H73 -> 0
A74: 052091702 | B74: DIPEL 2X 12 X 0.5 KG | C74: 69662 | D74: KG | E74: LACTOSE (SUGAR OF MILK), CRUDE | F74: EA | G74: 125 | H74: 1000 | I74: 300 | J74: 2 | K74: =VLOOKUP(A74,[1]Sheet1!$A$2:$C$284,3,FALSE) -> 0 | L74: =VLOOKUP(A74,[2]Sheet1!$A$115:$F$749,6,FALSE) -> 0 | M74: =(G74*K74)/H74 -> 0 | N74: =(L74*G74)/H74 -> 0
A75: 052091702 | B75: DIPEL 2X 12 X 0.5 KG | C75: 11309 | D75: KG | E75: Tergitol L-62 | F75: EA | G75: 10 | H75: 1000 | I75: 300 | J75: 2 | K75: =VLOOKUP(A75,[1]Sheet1!$A$2:$C$284,3,FALSE) -> 0 | L75: =VLOOKUP(A75,[2]Sheet1!$A$115:$F$749,6,FALSE) -> 0 | M75: =(G75*K75)/H75 -> 0 | N75: =(L75*G75)/H75 -> 0
A76: 052093001 | B76: GEODA 10 X 1 KG | C76: 77425 | D76: KG | E76: SIPERNAT®807A (SODIUM ALUMINOSILICATE) | F76: EA | G76: 4.692 | H76: 1000 | I76: 300 | J76: 4 | K76: =VLOOKUP(A76,[1]Sheet1!$A$2:$C$284,3,FALSE) -> 7200 | L76: =VLOOKUP(A76,[2]Sheet1!$A$115:$F$749,6,FALSE) -> 10000 | M76: =(G76*K76)/H76 -> 33.7824 | N76: =(L76*G76)/H76 -> 46.92
...

Sheet REACH Required
A1: Material | B1: Description | C1: FY21 Usage | D1: FY22 Fcst
A2: 21796 | B2: CORN COB GRANULES (5/8) HIGH BULK | C2: 182424.47 | D2: 48780.324
A3: 36052 | B3: MALTODEXTRIN, MALTRIN M100, NO N-CFR | C3: 121452.47 | D3: 115592.17
A4: 11907 | B4: PROPYLENE GLYCOL, BULK | C4: 107385.96 | D4: 4112290.4
A5: 18105 | B5: SODIUM SULFATE | C5: 86783.418 | D5: 86533.337
A6: 21795 | B6: CORN COB,10/14,Green Products | C6: 68117.53 | D6: 43188.6
A7: 55255 | B7: SODIUM LIGNOSULFON ULTRAZINE NA,NON-CFR | C7: 35675.314 | D7: 32441.388
A8: 68185 | B8: SORBITOL SOL70% NON-USP, NON-CFR | C8: 33866.355 | D8: 22065.228
A9: 50102 | B9: OIL, CORN (NOT NF) | C9: 24355.518 | D9: 10201.849
A10: 28887 | B10: LACTOSE 25 KG BAG | C10: 20796.175 | D10: 26666.424
A11: 57338 | B11: POLYOXYALKYLENE GLYCOL MACOL 16 NON-CFR | C11: 16974.869 | D11: 13010.986
A12: 51375 | B12: SPRAY OIL 10 | C12: 14926.999 | D12: 13048.601
A13: 57616 | B13: POLYSORBATE 20, NOT NF | C13: 12538.556 | D13: 12066.518
... A60: 70289 | B60: SURFACTANT, SURFYNOL - 485, NO N-CFR | C60: 0 | D60: 0
